<!-- Comments: Achieving simulation stability required: a) Fixing the rotation of the leg, b) Limiting the control range from 0 to 1 for the pusher. Playing with contact parameters didn't help. -->

<mujoco model="framed hopper">
    <compiler angle="radian"/>
	<option timestep="0.002" iterations="1" ls_iterations="4" solver="Newton" gravity="0 0 -9.81">
		<flag eulerdamp="disable"/>
	</option>
    <worldbody>
        <light cutoff="100" diffuse="1 1 1" dir="-0 0 -1.3" directional="true" exponent="1" pos="0 0 1.3" specular=".1 .1 .1"/>
        <geom conaffinity="1" condim="3" name="floor" pos="0 0 0" rgba="0.8 0.9 0.8 1" size="20 20 .125" type="plane" material="MatPlane"/>
        <body name="ball" pos="0 0 0.1">
            <camera name="track" pos="0 -3 0.3" xyaxes="1 0 0 0 1 5" mode="track"/>
            <joint axis="1 0 0" pos="0 0 -0.1" limited="false" name="rootx" type="slide"/>
            <joint axis="0 0 1" pos="0 0 -0.1" limited="false" name="rootz" type="slide"/>
            <geom name="ball_geom" size="0.1" type="sphere" conaffinity="0" contype="1"/>
            <body name="leg_push" pos="0 0 0" axisangle ="0 1 0 0.5">
                <joint axis="0 0 -1" name="leg_joint_push" pos="0 0 0" range="0.0 0.15" type="slide"/>
                <geom friction="0.8" name="leg_geom" size="0.025 0.075" type="capsule" conaffinity="0" contype="1"/>
            </body>
        </body>
    </worldbody>
    <actuator>
        <motor ctrllimited="true" ctrlrange="0.0 1.0" gear="200.0" joint="leg_joint_push"/>
    </actuator>
    <asset>
        <texture type="skybox" builtin="gradient" rgb1=".4 .5 .6" rgb2="0 0 0"
            width="100" height="100"/>
        <texture builtin="flat" height="1278" mark="cross" markrgb="1 1 1" name="texgeom" random="0.01" rgb1="0.8 0.6 0.4" rgb2="0.8 0.6 0.4" type="cube" width="127"/>
        <texture type="2d" name="texplane" builtin="checker" mark="edge" rgb1="0.2 0.3 0.4" rgb2="0.1 0.2 0.3"
        markrgb="0.8 0.8 0.8" width="100" height="100"/>
        <material name="MatPlane" texture="texplane" texuniform="true" texrepeat="5 5" reflectance="0.2"/>
        <material name="geom" texture="texgeom" texuniform="true"/>
    </asset>
</mujoco>